Workbook

Sheet Read Me
A1: Sample Trial Balance with Schedule III Mapping
A3: Company | B3: XYZ Manufacturing Private Limited (fictitious - sample data only)
A4: Periods | B4: Current Year (CY): FY 2025-26 (year ended 31 March 2026) | Previous Year (PY): FY 2024-25 (year ended 31 March 2025)
A5: Framework | B5: Companies Act, 2013 - Schedule III, Division I (non-Ind AS / Accounting Standards), Part I (Balance Sheet) and Part II (Statement of P&L)
A6: Units | B6: INR in Lakhs
A8: Sheets
A9: Trial Balance | B9: GL-level adjusted trial balance (CY & PY Dr/Cr) with each GL mapped to a Schedule III line item via Mapping Code.
A10: Mapping | B10: Master of Schedule III line items. Change a GL's Mapping Code on the Trial Balance and everything re-flows.
A11: Balance Sheet | B11: Schedule III Part I - built from Trial Balance by SUMIFS on Mapping Code (CY & PY).
A12: Statement of P&L | B12: Schedule III Part II - built from Trial Balance by SUMIFS on Mapping Code (CY & PY).
A13: Checks | B13: Integrity checks: TB balances, all GLs mapped, BS balances, and reconciliations between P&L and balance sheet.
A15: Colour legend | B15: Blue = hardcoded input | Black = formula | Green = cross-sheet link/lookup | Yellow = cells to edit when using your own data
A17: Assumptions
A18: 1 | B18: All figures are illustrative and fictitious. Trial balance is post-adjustment (closing stock, depreciation, provisions already booked) but before closing of P&L to reserves.
A19: 2 | B19: Sign convention: TB shows Debit and Credit columns; Net = Dr - Cr. Liabilities, equity and income are presented as positive on the Balance Sheet / P&L by reversing the sign.
A20: 3 | B20: Opening surplus: PY opening (513) is a balancing figure so the PY TB balances. CY opening surplus (1,071) = PY opening 513 + PY profit after tax 558 (no dividend or reserve transfer assumed).
A21: 4 | B21: CY bank balance (current account, 288) is a balancing figure so the CY TB balances.
A22: 5 | B22: Reserves and surplus on the Balance Sheet = securities premium + general reserve + opening surplus + profit for the year from the P&L.
A23: 6 | B23: Tangible assets and intangible assets are shown net of accumulated depreciation/amortisation (gross block and accumulated balances are mapped to the same line item).
A24: 7 | B24: Fixed deposits with original maturity > 3 months are shown under Other bank balances; margin money FDs > 12 months under Other non-current assets.
A25: 8 | B25: Current maturities of long-term debt, statutory dues, advance from customers, salaries payable and accrued interest are grouped under Other current liabilities.
A26: 9 | B26: Advance tax/TDS, GST input credit, prepaid expenses, supplier advances and employee loans are grouped under Short-term loans and advances.
A27: 10 | B27: Tax is computed at an assumed ~25.17% effective rate on profit before tax (current tax + deferred tax). No MAT, exceptional items or dividends are assumed.
A28: 11 | B28: If your entity follows Ind AS, use Division II of Schedule III (financial-asset/liability based classification); the mapping codes would need to be restructured.

Sheet Trial Balance
A1: XYZ Manufacturing Private Limited - Trial Balance with Schedule III Mapping
A2: CY = year ended 31 March 2026 | PY = year ended 31 March 2025 | INR in Lakhs | Mapping Code (col D) is the input that drives the Schedule III lookups (cols E-H)
A4: GL Code | B4: GL Account Name | C4: Account Type | D4: Mapping Code | E4: Statement | F4: Sub-section | G4: Schedule III Line Item | H4: Note No. | I4: Note Component / Sub-classification | J4: CY Debit | K4: CY Credit | L4: PY Debit | M4: PY Credit | N4: CY Net (Dr-Cr) | O4: PY Net (Dr-Cr)
A5: 1001 | B5: Equity Share Capital - Issued, Subscribed & Paid-up | C5: Equity | D5: BS-EL-01 | E5: =IFERROR(INDEX(Mapping!$B$5:$B$41,MATCH($D5,Mapping!$A$5:$A$41,0)),"UNMAPPED") -> Balance Sheet | F5: =IFERROR(INDEX(Mapping!$D$5:$D$41,MATCH($D5,Mapping!$A$5:$A$41,0)),"UNMAPPED") -> Shareholders' funds | G5: =IFERROR(INDEX(Mapping!$E$5:$E$41,MATCH($D5,Mapping!$A$5:$A$41,0)),"UNMAPPED") -> Share capital | H5: =IFERROR(INDEX(Mapping!$F$5:$F$41,MATCH($D5,Mapping!$A$5:$A$41,0)),"UNMAPPED") -> 1 | I5: Equity share capital | K5: 1000 | M5: 1000 | N5: =J5-K5 -> -1000 | O5: =L5-M5 -> -1000
A6: 1002 | B6: Securities Premium Account | C6: Equity | D6: BS-EL-02 | E6: =IFERROR(INDEX(Mapping!$B$5:$B$41,MATCH($D6,Mapping!$A$5:$A$41,0)),"UNMAPPED") -> Balance Sheet | F6: =IFERROR(INDEX(Mapping!$D$5:$D$41,MATCH($D6,Mapping!$A$5:$A$41,0)),"UNMAPPED") -> Shareholders' funds | G6: =IFERROR(INDEX(Mapping!$E$5:$E$41,MATCH($D6,Mapping!$A$5:$A$41,0)),"UNMAPPED") -> Reserves and surplus | H6: =IFERROR(INDEX(Mapping!$F$5:$F$41,MATCH($D6,Mapping!$A$5:$A$41,0)),"UNMAPPED") -> 2 | I6: Securities premium | K6: 500 | M6: 500 | N6: =J6-K6 -> -500 | O6: =L6-M6 -> -500
A7: 1003 | B7: General Reserve | C7: Equity | D7: BS-EL-02 | E7: =IFERROR(INDEX(Mapping!$B$5:$B$41,MATCH($D7,Mapping!$A$5:$A$41,0)),"UNMAPPED") -> Balance Sheet | F7: =IFERROR(INDEX(Mapping!$D$5:$D$41,MATCH($D7,Mapping!$A$5:$A$41,0)),"UNMAPPED") -> Shareholders' funds | G7: =IFERROR(INDEX(Mapping!$E$5:$E$41,MATCH($D7,Mapping!$A$5:$A$41,0)),"UNMAPPED") -> Reserves and surplus | H7: =IFERROR(INDEX(Mapping!$F$5:$F$41,MATCH($D7,Mapping!$A$5:$A$41,0)),"UNMAPPED") -> 2 | I7: General reserve | K7: 300 | M7: 300 | N7: =J7-K7 -> -300 | O7: =L7-M7 -> -300
A8: 1004 | B8: Surplus in Statement of P&L - Opening Balance | C8: Equity | D8: BS-EL-02 | E8: =IFERROR(INDEX(Mapping!$B$5:$B$41,MATCH($D8,Mapping!$A$5:$A$41,0)),"UNMAPPED") -> Balance Sheet | F8: =IFERROR(INDEX(Mapping!$D$5:$D$41,MATCH($D8,Mapping!$A$5:$A$41,0)),"UNMAPPED") -> Shareholders' funds | G8: =IFERROR(INDEX(Mapping!$E$5:$E$41,MATCH($D8,Mapping!$A$5:$A$41,0)),"UNMAPPED") -> Reserves and surplus | H8: =IFERROR(INDEX(Mapping!$F$5:$F$41,MATCH($D8,Mapping!$A$5:$A$41,0)),"UNMAPPED") -> 2 | I8: Surplus (opening balance) | K8: 1071 | M8: 513 | N8: =J8-K8 -> -1071 | O8: =L8-M8 -> -513
A9: 2001 | B9: Term Loan - State Bank of India (Secured) | C9: Liability | D9: BS-EL-03 | E9: =IFERROR(INDEX(Mapping!$B$5:$B$41,MATCH($D9,Mapping!$A$5:$A$41,0)),"UNMAPPED") -> Balance Sheet | F9: =IFERROR(INDEX(Mapping!$D$5:$D$41,MATCH($D9,Mapping!$A$5:$A$41,0)),"UNMAPPED") -> Non-current liabilities | G9: =IFERROR(INDEX(Mapping!$E$5:$E$41,MATCH($D9,Mapping!$A$5:$A$41,0)),"UNMAPPED") -> Long-term borrowings | H9: =IFERROR(INDEX(Mapping!$F$5:$F$41,MATCH($D9,Mapping!$A$5:$A$41,0)),"UNMAPPED") -> 3 | I9: Term loans from banks (secured) | K9: 1200 | M9: 1500 | N9: =J9-K9 -> -1200 | O9: =L9-M9 -> -1500
A10: 2010 | B10: Deferred Tax Liability (Net) | C10: Liability | D10: BS-EL-04 | E10: =IFERROR(INDEX(Mapping!$B$5:$B$41,MATCH($D10,Mapping!$A$5:$A$41,0)),"UNMAPPED") -> Balance Sheet | F10: =IFERROR(INDEX(Mapping!$D$5:$D$41,MATCH($D10,Mapping!$A$5:$A$41,0)),"UNMAPPED") -> Non-current liabilities | G10: =IFERROR(INDEX(Mapping!$E$5:$E$41,MATCH($D10,Mapping!$A$5:$A$41,0)),"UNMAPPED") -> Deferred tax liabilities (net) | H10: =IFERROR(INDEX(Mapping!$F$5:$F$41,MATCH($D10,Mapping!$A$5:$A$41,0)),"UNMAPPED") -> 4 | I10: Deferred tax liability | K10: 95 | M10: 80 | N10: =J10-K10 -> -95 | O10: =L10-M10 -> -80
A11: 2020 | B11: Provision for Gratuity - Non-current | C11: Liability | D11: BS-EL-06 | E11: =IFERROR(INDEX(Mapping!$B$5:$B$41,MATCH($D11,Mapping!$A$5:$A$41,0)),"UNMAPPED") -> Balance Sheet | F11: =IFERROR(INDEX(Mapping!$D$5:$D$41,MATCH($D11,Mapping!$A$5:$A$41,0)),"UNMAPPED") -> Non-current liabilities | G11: =IFERROR(INDEX(Mapping!$E$5:$E$41,MATCH($D11,Mapping!$A$5:$A$41,0)),"UNMAPPED") -> Long-term provisions | H11: =IFERROR(INDEX(Mapping!$F$5:$F$41,MATCH($D11,Mapping!$A$5:$A$41,0)),"UNMAPPED") -> 6 | I11: Provision for employee benefits | K11: 150 | M11: 120 | N11: =J11-K11 -> -150 | O11: =L11-M11 -> -120
A12: 2101 | B12: Cash Credit - HDFC Bank (Secured) | C12: Liability | D12: BS-EL-07 | E12: =IFERROR(INDEX(Mapping!$B$5:$B$41,MATCH($D12,Mapping!$A$5:$A$41,0)),"UNMAPPED") -> Balance Sheet | F12: =IFERROR(INDEX(Mapping!$D$5:$D$41,MATCH($D12,Mapping!$A$5:$A$41,0)),"UNMAPPED") -> Current liabilities | G12: =IFERROR(INDEX(Mapping!$E$5:$E$41,MATCH($D12,Mapping!$A$5:$A$41,0)),"UNMAPPED") -> Short-term borrowings | H12: =IFERROR(INDEX(Mapping!$F$5:$F$41,MATCH($D12,Mapping!$A$5:$A$41,0)),"UNMAPPED") -> 7 | I12: Loans repayable on demand - banks | K12: 500 | M12: 600 | N12: =J12-K12 -> -500 | O12: =L12-M12 -> -600
A13: 2110 | B13: Trade Payables - MSME Vendors | C13: Liability | D13: BS-EL-08 | E13: =IFERROR(INDEX(Mapping!$B$5:$B$41,MATCH($D13,Mapping!$A$5:$A$41,0)),"UNMAPPED") -> Balance Sheet | F13: =IFERROR(INDEX(Mapping!$D$5:$D$41,MATCH($D13,Mapping!$A$5:$A$41,0)),"UNMAPPED") -> Current liabilities | G13: =IFERROR(INDEX(Mapping!$E$5:$E$41,MATCH($D13,Mapping!$A$5:$A$41,0)),"UNMAPPED") -> Trade payables | H13: =IFERROR(INDEX(Mapping!$F$5:$F$41,MATCH($D13,Mapping!$A$5:$A$41,0)),"UNMAPPED") -> 8 | I13: Total outstanding dues of MSMEs | K13: 180 | M13: 150 | N13: =J13-K13 -> -180 | O13: =L13-M13 -> -150
A14: 2111 | B14: Trade Payables - Other Vendors | C14: Liability | D14: BS-EL-08 | E14: =IFERROR(INDEX(Mapping!$B$5:$B$41,MATCH($D14,Mapping!$A$5:$A$41,0)),"UNMAPPED") -> Balance Sheet | F14: =IFERROR(INDEX(Mapping!$D$5:$D$41,MATCH($D14,Mapping!$A$5:$A$41,0)),"UNMAPPED") -> Current liabilities | G14: =IFERROR(INDEX(Mapping!$E$5:$E$41,MATCH($D14,Mapping!$A$5:$A$41,0)),"UNMAPPED") -> Trade payables | H14: =IFERROR(INDEX(Mapping!$F$5:$F$41,MATCH($D14,Mapping!$A$5:$A$41,0)),"UNMAPPED") -> 8 | I14: Total outstanding dues of creditors other than MSMEs | K14: 920 | M14: 850 | N14: =J14-K14 -> -920 | O14: =L14-M14 -> -850
A15: 2120 | B15: Current Maturities of Long-term Debt | C15: Liability | D15: BS-EL-09 | E15: =IFERROR(INDEX(Mapping!$B$5:$B$41,MATCH($D15,Mapping!$A$5:$A$41,0)),"UNMAPPED") -> Balance Sheet | F15: =IFERROR(INDEX(Mapping!$D$5:$D$41,MATCH($D15,Mapping!$A$5:$A$41,0)),"UNMAPPED") -> Current liabilities | G15: =IFERROR(INDEX(Mapping!$E$5:$E$41,MATCH($D15,Mapping!$A$5:$A$41,0)),"UNMAPPED") -> Other current liabilities | H15: =IFERROR(INDEX(Mapping!$F$5:$F$41,MATCH($D15,Mapping!$A$5:$A$41,0)),"UNMAPPED") -> 9 | I15: Current maturities of long-term debt | K15: 300 | M15: 300 | N15: =J15-K15 -> -300 | O15: =L15-M15 -> -300
A16: 2121 | B16: Interest Accrued but not Due on Borrowings | C16: Liability | D16: BS-EL-09 | E16: =IFERROR(INDEX(Mapping!$B$5:$B$41,MATCH($D16,Mapping!$A$5:$A$41,0)),"UNMAPPED") -> Balance Sheet | F16: =IFERROR(INDEX(Mapping!$D$5:$D$41,MATCH($D16,Mapping!$A$5:$A$41,0)),"UNMAPPED") -> Current liabilities | G16: =IFERROR(INDEX(Mapping!$E$5:$E$41,MATCH($D16,Mapping!$A$5:$A$41,0)),"UNMAPPED") -> Other current liabilities | H16: =IFERROR(INDEX(Mapping!$F$5:$F$41,MATCH($D16,Mapping!$A$5:$A$41,0)),"UNMAPPED") -> 9 | I16: Interest accrued but not due | K16: 10 | M16: 12 | N16: =J16-K16 -> -10 | O16: =L16-M16 -> -12
... A23: 2131 | B23: Provision for Income Tax | C23: Liability | D23: BS-EL-10 | E23: =IFERROR(INDEX(Mapping!$B$5:$B$41,MATCH($D23,Mapping!$A$5:$A$41,0)),"UNMAPPED") -> Balance Sheet | F23: =IFERROR(INDEX(Mapping!$D$5:$D$41,MATCH($D23,Mapping!$A$5:$A$41,0)),"UNMAPPED") -> Current liabilities | G23: =IFERROR(INDEX(Mapping!$E$5:$E$41,MATCH($D23,Mapping!$A$5:$A$41,0)),"UNMAPPED") -> Short-term provisions | H23: =IFERROR(INDEX(Mapping!$F$5:$F$41,MATCH($D23,Mapping!$A$5:$A$41,0)),"UNMAPPED") -> 10 | I23: Provision for tax | K23: 190 | M23: 160 | N23: =J23-K23 -> -190 | O23: =L23-M23 -> -160
A24: 3001 | B24: Freehold Land | C24: Asset | D24: BS-A-01 | E24: =IFERROR(INDEX(Mapping!$B$5:$B$41,MATCH($D24,Mapping!$A$5:$A$41,0)),"UNMAPPED") -> Balance Sheet | F24: =IFERROR(INDEX(Mapping!$D$5:$D$41,MATCH($D24,Mapping!$A$5:$A$41,0)),"UNMAPPED") -> Non-current assets | G24: =IFERROR(INDEX(Mapping!$E$5:$E$41,MATCH($D24,Mapping!$A$5:$A$41,0)),"UNMAPPED") -> Fixed assets - Tangible assets | H24: =IFERROR(INDEX(Mapping!$F$5:$F$41,MATCH($D24,Mapping!$A$5:$A$41,0)),"UNMAPPED") -> 11 | I24: Land | J24: 800 | L24: 800 | N24: =J24-K24 -> 800 | O24: =L24-M24 -> 800
A25: 3002 | B25: Buildings - Gross Block | C25: Asset | D25: BS-A-01 | E25: =IFERROR(INDEX(Mapping!$B$5:$B$41,MATCH($D25,Mapping!$A$5:$A$41,0)),"UNMAPPED") -> Balance Sheet | F25: =IFERROR(INDEX(Mapping!$D$5:$D$41,MATCH($D25,Mapping!$A$5:$A$41,0)),"UNMAPPED") -> Non-current assets | G25: =IFERROR(INDEX(Mapping!$E$5:$E$41,MATCH($D25,Mapping!$A$5:$A$41,0)),"UNMAPPED") -> Fixed assets - Tangible assets | H25: =IFERROR(INDEX(Mapping!$F$5:$F$41,MATCH($D25,Mapping!$A$5:$A$41,0)),"UNMAPPED") -> 11 | I25: Buildings | J25: 900 | L25: 900 | N25: =J25-K25 -> 900 | O25: =L25-M25 -> 900
A26: 3003 | B26: Plant & Machinery - Gross Block | C26: Asset | D26: BS-A-01 | E26: =IFERROR(INDEX(Mapping!$B$5:$B$41,MATCH($D26,Mapping!$A$5:$A$41,0)),"UNMAPPED") -> Balance Sheet | F26: =IFERROR(INDEX(Mapping!$D$5:$D$41,MATCH($D26,Mapping!$A$5:$A$41,0)),"UNMAPPED") -> Non-current assets | G26: =IFERROR(INDEX(Mapping!$E$5:$E$41,MATCH($D26,Mapping!$A$5:$A$41,0)),"UNMAPPED") -> Fixed assets - Tangible assets | H26: =IFERROR(INDEX(Mapping!$F$5:$F$41,MATCH($D26,Mapping!$A$5:$A$41,0)),"UNMAPPED") -> 11 | I26: Plant and equipment | J26: 2500 | L26: 2200 | N26: =J26-K26 -> 2500 | O26: =L26-M26 -> 2200
A27: 3004 | B27: Furniture & Fixtures - Gross Block | C27: Asset | D27: BS-A-01 | E27: =IFERROR(INDEX(Mapping!$B$5:$B$41,MATCH($D27,Mapping!$A$5:$A$41,0)),"UNMAPPED") -> Balance Sheet | F27: =IFERROR(INDEX(Mapping!$D$5:$D$41,MATCH($D27,Mapping!$A$5:$A$41,0)),"UNMAPPED") -> Non-current assets | G27: =IFERROR(INDEX(Mapping!$E$5:$E$41,MATCH($D27,Mapping!$A$5:$A$41,0)),"UNMAPPED") -> Fixed assets - Tangible assets | H27: =IFERROR(INDEX(Mapping!$F$5:$F$41,MATCH($D27,Mapping!$A$5:$A$41,0)),"UNMAPPED") -> 11 | I27: Furniture and fixtures | J27: 170 | L27: 150 | N27: =J27-K27 -> 170 | O27: =L27-M27 -> 150
A28: 3005 | B28: Vehicles - Gross Block | C28: Asset | D28: BS-A-01 | E28: =IFERROR(INDEX(Mapping!$B$5:$B$41,MATCH($D28,Mapping!$A$5:$A$41,0)),"UNMAPPED") -> Balance Sheet | F28: =IFERROR(INDEX(Mapping!$D$5:$D$41,MATCH($D28,Mapping!$A$5:$A$41,0)),"UNMAPPED") -> Non-current assets | G28: =IFERROR(INDEX(Mapping!$E$5:$E$41,MATCH($D28,Mapping!$A$5:$A$41,0)),"UNMAPPED") -> Fixed assets - Tangible assets | H28: =IFERROR(INDEX(Mapping!$F$5:$F$41,MATCH($D28,Mapping!$A$5:$A$41,0)),"UNMAPPED") -> 11 | I28: Vehicles | J28: 120 | L28: 120 | N28: =J28-K28 -> 120 | O28: =L28-M28 -> 120
A29: 3006 | B29: Computers & IT Equipment - Gross Block | C29: Asset | D29: BS-A-01 | E29: =IFERROR(INDEX(Mapping!$B$5:$B$41,MATCH($D29,Mapping!$A$5:$A$41,0)),"UNMAPPED") -> Balance Sheet | F29: =IFERROR(INDEX(Mapping!$D$5:$D$41,MATCH($D29,Mapping!$A$5:$A$41,0)),"UNMAPPED") -> Non-current assets | G29: =IFERROR(INDEX(Mapping!$E$5:$E$41,MATCH($D29,Mapping!$A$5:$A$41,0)),"UNMAPPED") -> Fixed assets - Tangible assets | H29: =IFERROR(INDEX(Mapping!$F$5:$F$41,MATCH($D29,Mapping!$A$5:$A$41,0)),"UNMAPPED") -> 11 | I29: Office equipment / computers | J29: 150 | L29: 130 | N29: =J29-K29 -> 150 | O29: =L29-M29 -> 130
A30: 3011 | B30: Accumulated Depreciation - Buildings | C30: Asset | D30: BS-A-01 | E30: =IFERROR(INDEX(Mapping!$B$5:$B$41,MATCH($D30,Mapping!$A$5:$A$41,0)),"UNMAPPED") -> Balance Sheet | F30: =IFERROR(INDEX(Mapping!$D$5:$D$41,MATCH($D30,Mapping!$A$5:$A$41,0)),"UNMAPPED") -> Non-current assets | G30: =IFERROR(INDEX(Mapping!$E$5:$E$41,MATCH($D30,Mapping!$A$5:$A$41,0)),"UNMAPPED") -> Fixed assets - Tangible assets | H30: =IFERROR(INDEX(Mapping!$F$5:$F$41,MATCH($D30,Mapping!$A$5:$A$41,0)),"UNMAPPED") -> 11 | I30: Buildings (accumulated depreciation) | K30: 225 | M30: 180 | N30: =J30-K30 -> -225 | O30: =L30-M30 -> -180
A31: 3012 | B31: Accumulated Depreciation - Plant & Machinery | C31: Asset | D31: BS-A-01 | E31: =IFERROR(INDEX(Mapping!$B$5:$B$41,MATCH($D31,Mapping!$A$5:$A$41,0)),"UNMAPPED") -> Balance Sheet | F31: =IFERROR(INDEX(Mapping!$D$5:$D$41,MATCH($D31,Mapping!$A$5:$A$41,0)),"UNMAPPED") -> Non-current assets | G31: =IFERROR(INDEX(Mapping!$E$5:$E$41,MATCH($D31,Mapping!$A$5:$A$41,0)),"UNMAPPED") -> Fixed assets - Tangible assets | H31: =IFERROR(INDEX(Mapping!$F$5:$F$41,MATCH($D31,Mapping!$A$5:$A$41,0)),"UNMAPPED") -> 11 | I31: Plant and equipment (accumulated depreciation) | K31: 950 | M31: 700 | N31: =J31-K31 -> -950 | O31: =L31-M31 -> -700
A32: 3013 | B32: Accumulated Depreciation - Furniture & Fixtures | C32: Asset | D32: BS-A-01 | E32: =IFERROR(INDEX(Mapping!$B$5:$B$41,MATCH($D32,Mapping!$A$5:$A$41,0)),"UNMAPPED") -> Balance Sheet | F32: =IFERROR(INDEX(Mapping!$D$5:$D$41,MATCH($D32,Mapping!$A$5:$A$41,0)),"UNMAPPED") -> Non-current assets | G32: =IFERROR(INDEX(Mapping!$E$5:$E$41,MATCH($D32,Mapping!$A$5:$A$41,0)),"UNMAPPED") -> Fixed assets - Tangible assets | H32: =IFERROR(INDEX(Mapping!$F$5:$F$41,MATCH($D32,Mapping!$A$5:$A$41,0)),"UNMAPPED") -> 11 | I32: Furniture and fixtures (accumulated depreciation) | K32: 75 | M32: 60 | N32: =J32-K32 -> -75 | O32: =L32-M32 -> -60
A33: 3014 | B33: Accumulated Depreciation - Vehicles | C33: Asset | D33: BS-A-01 | E33: =IFERROR(INDEX(Mapping!$B$5:$B$41,MATCH($D33,Mapping!$A$5:$A$41,0)),"UNMAPPED") -> Balance Sheet | F33: =IFERROR(INDEX(Mapping!$D$5:$D$41,MATCH($D33,Mapping!$A$5:$A$41,0)),"UNMAPPED") -> Non-current assets | G33: =IFERROR(INDEX(Mapping!$E$5:$E$41,MATCH($D33,Mapping!$A$5:$A$41,0)),"UNMAPPED") -> Fixed assets - Tangible assets | H33: =IFERROR(INDEX(Mapping!$F$5:$F$41,MATCH($D33,Mapping!$A$5:$A$41,0)),"UNMAPPED") -> 11 | I33: Vehicles (accumulated depreciation) | K33: 70 | M33: 50 | N33: =J33-K33 -> -70 | O33: =L33-M33 -> -50
A34: 3015 | B34: Accumulated Depreciation - Computers & IT | C34: Asset | D34: BS-A-01 | E34: =IFERROR(INDEX(Mapping!$B$5:$B$41,MATCH($D34,Mapping!$A$5:$A$41,0)),"UNMAPPED") -> Balance Sheet | F34: =IFERROR(INDEX(Mapping!$D$5:$D$41,MATCH($D34,Mapping!$A$5:$A$41,0)),"UNMAPPED") -> Non-current assets | G34: =IFERROR(INDEX(Mapping!$E$5:$E$41,MATCH($D34,Mapping!$A$5:$A$41,0)),"UNMAPPED") -> Fixed assets - Tangible assets | H34: =IFERROR(INDEX(Mapping!$F$5:$F$41,MATCH($D34,Mapping!$A$5:$A$41,0)),"UNMAPPED") -> 11 | I34: Office equipment / computers (accumulated depreciation) | K34: 95 | M34: 70 | N34: =J34-K34 -> -95 | O34: =L34-M34 -> -70
A35: 3021 | B35: Computer Software - Gross Block | C35: Asset | D35: BS-A-02 | E35: =IFERROR(INDEX(Mapping!$B$5:$B$41,MATCH($D35,Mapping!$A$5:$A$41,0)),"UNMAPPED") -> Balance Sheet | F35: =IFERROR(INDEX(Mapping!$D$5:$D$41,MATCH($D35,Mapping!$A$5:$A$41,0)),"UNMAPPED") -> Non-current assets | G35: =IFERROR(INDEX(Mapping!$E$5:$E$41,MATCH($D35,Mapping!$A$5:$A$41,0)),"UNMAPPED") -> Fixed assets - Intangible assets | H35: =IFERROR(INDEX(Mapping!$F$5:$F$41,MATCH($D35,Mapping!$A$5:$A$41,0)),"UNMAPPED") -> 12 | I35: Computer software | J35: 100 | L35: 80 | N35: =J35-K35 -> 100 | O35: =L35-M35 -> 80
A36: 3022 | B36: Accumulated Amortisation - Software | C36: Asset | D36: BS-A-02 | E36: =IFERROR(INDEX(Mapping!$B$5:$B$41,MATCH($D36,Mapping!$A$5:$A$41,0)),"UNMAPPED") -> Balance Sheet | F36: =IFERROR(INDEX(Mapping!$D$5:$D$41,MATCH($D36,Mapping!$A$5:$A$41,0)),"UNMAPPED") -> Non-current assets | G36: =IFERROR(INDEX(Mapping!$E$5:$E$41,MATCH($D36,Mapping!$A$5:$A$41,0)),"UNMAPPED") -> Fixed assets - Intangible assets | H36: =IFERROR(INDEX(Mapping!$F$5:$F$41,MATCH($D36,Mapping!$A$5:$A$41,0)),"UNMAPPED") -> 12 | I36: Computer software (accumulated amortisation) | K36: 45 | M36: 30 | N36: =J36-K36 -> -45 | O36: =L36-M36 -> -30
A37: 3031 | B37: Capital Work-in-Progress | C37: Asset | D37: BS-A-03 | E37: =IFERROR(INDEX(Mapping!$B$5:$B$41,MATCH($D37,Mapping!$A$5:$A$41,0)),"UNMAPPED") -> Balance Sheet | F37: =IFERROR(INDEX(Mapping!$D$5:$D$41,MATCH($D37,Mapping!$A$5:$A$41,0)),"UNMAPPED") -> Non-current assets | G37: =IFERROR(INDEX(Mapping!$E$5:$E$41,MATCH($D37,Mapping!$A$5:$A$41,0)),"UNMAPPED") -> Fixed assets - Capital work-in-progress | H37: =IFERROR(INDEX(Mapping!$F$5:$F$41,MATCH($D37,Mapping!$A$5:$A$41,0)),"UNMAPPED") -> 13 | I37: Capital work-in-progress | J37: 200 | L37: 150 | N37: =J37-K37 -> 200 | O37: =L37-M37 -> 150
A38: 3041 | B38: Investment in Equity Shares of Subsidiary (Unquoted) | C38: Asset | D38: BS-A-05 | E38: =IFERROR(INDEX(Mapping!$B$5:$B$41,MATCH($D38,Mapping!$A$5:$A$41,0)),"UNMAPPED") -> Balance Sheet | F38: =IFERROR(INDEX(Mapping!$D$5:$D$41,MATCH($D38,Mapping!$A$5:$A$41,0)),"UNMAPPED") -> Non-current assets | G38: =IFERROR(INDEX(Mapping!$E$5:$E$41,MATCH($D38,Mapping!$A$5:$A$41,0)),"UNMAPPED") -> Non-current investments | H38: =IFERROR(INDEX(Mapping!$F$5:$F$41,MATCH($D38,Mapping!$A$5:$A$41,0)),"UNMAPPED") -> 15 | I38: Investment in equity instruments - subsidiary | J38: 250 | L38: 250 | N38: =J38-K38 -> 250 | O38: =L38-M38 -> 250
A39: 3051 | B39: Security Deposits (Electricity, Rent, etc.) | C39: Asset | D39: BS-A-07 | E39: =IFERROR(INDEX(Mapping!$B$5:$B$41,MATCH($D39,Mapping!$A$5:$A$41,0)),"UNMAPPED") -> Balance Sheet | F39: =IFERROR(INDEX(Mapping!$D$5:$D$41,MATCH($D39,Mapping!$A$5:$A$41,0)),"UNMAPPED") -> Non-current assets | G39: =IFERROR(INDEX(Mapping!$E$5:$E$41,MATCH($D39,Mapping!$A$5:$A$41,0)),"UNMAPPED") -> Long-term loans and advances | H39: =IFERROR(INDEX(Mapping!$F$5:$F$41,MATCH($D39,Mapping!$A$5:$A$41,0)),"UNMAPPED") -> 17 | I39: Security deposits | J39: 65 | L39: 60 | N39: =J39-K39 -> 65 | O39: =L39-M39 -> 60
A40: 3052 | B40: Capital Advances | C40: Asset | D40: BS-A-07 | E40: =IFERROR(INDEX(Mapping!$B$5:$B$41,MATCH($D40,Mapping!$A$5:$A$41,0)),"UNMAPPED") -> Balance Sheet | F40: =IFERROR(INDEX(Mapping!$D$5:$D$41,MATCH($D40,Mapping!$A$5:$A$41,0)),"UNMAPPED") -> Non-current assets | G40: =IFERROR(INDEX(Mapping!$E$5:$E$41,MATCH($D40,Mapping!$A$5:$A$41,0)),"UNMAPPED") -> Long-term loans and advances | H40: =IFERROR(INDEX(Mapping!$F$5:$F$41,MATCH($D40,Mapping!$A$5:$A$41,0)),"UNMAPPED") -> 17 | I40: Capital advances | J40: 30 | L40: 40 | N40: =J40-K40 -> 30 | O40: =L40-M40 -> 40
A41: 3061 | B41: Long-term Fixed Deposits - Margin Money against LCs/BGs | C41: Asset | D41: BS-A-08 | E41: =IFERROR(INDEX(Mapping!$B$5:$B$41,MATCH($D41,Mapping!$A$5:$A$41,0)),"UNMAPPED") -> Balance Sheet | F41: =IFERROR(INDEX(Mapping!$D$5:$D$41,MATCH($D41,Mapping!$A$5:$A$41,0)),"UNMAPPED") -> Non-current assets | G41: =IFERROR(INDEX(Mapping!$E$5:$E$41,MATCH($D41,Mapping!$A$5:$A$41,0)),"UNMAPPED") -> Other non-current assets | H41: =IFERROR(INDEX(Mapping!$F$5:$F$41,MATCH($D41,Mapping!$A$5:$A$41,0)),"UNMAPPED") -> 18 | I41: Long-term bank deposits (maturity > 12 months) | J41: 50 | L41: 50 | N41: =J41-K41 -> 50 | O41: =L41-M41 -> 50
A42: 3101 | B42: Investment in Mutual Funds (Liquid / Debt) | C42: Asset | D42: BS-A-09 | E42: =IFERROR(INDEX(Mapping!$B$5:$B$41,MATCH($D42,Mapping!$A$5:$A$41,0)),"UNMAPPED") -> Balance Sheet | F42: =IFERROR(INDEX(Mapping!$D$5:$D$41,MATCH($D42,Mapping!$A$5:$A$41,0)),"UNMAPPED") -> Current assets | G42: =IFERROR(INDEX(Mapping!$E$5:$E$41,MATCH($D42,Mapping!$A$5:$A$41,0)),"UNMAPPED") -> Current investments | H42: =IFERROR(INDEX(Mapping!$F$5:$F$41,MATCH($D42,Mapping!$A$5:$A$41,0)),"UNMAPPED") -> 19 | I42: Investments in mutual funds | J42: 150 | L42: 100 | N42: =J42-K42 -> 150 | O42: =L42-M42 -> 100
A43: 3111 | B43: Raw Materials & Components | C43: Asset | D43: BS-A-10 | E43: =IFERROR(INDEX(Mapping!$B$5:$B$41,MATCH($D43,Mapping!$A$5:$A$41,0)),"UNMAPPED") -> Balance Sheet | F43: =IFERROR(INDEX(Mapping!$D$5:$D$41,MATCH($D43,Mapping!$A$5:$A$41,0)),"UNMAPPED") -> Current assets | G43: =IFERROR(INDEX(Mapping!$E$5:$E$41,MATCH($D43,Mapping!$A$5:$A$41,0)),"UNMAPPED") -> Inventories | H43: =IFERROR(INDEX(Mapping!$F$5:$F$41,MATCH($D43,Mapping!$A$5:$A$41,0)),"UNMAPPED") -> 20 | I43: Raw materials | J43: 520 | L43: 450 | N43: =J43-K43 -> 520 | O43: =L43-M43 -> 450
A44: 3112 | B44: Work-in-Progress | C44: Asset | D44: BS-A-10 | E44: =IFERROR(INDEX(Mapping!$B$5:$B$41,MATCH($D44,Mapping!$A$5:$A$41,0)),"UNMAPPED") -> Balance Sheet | F44: =IFERROR(INDEX(Mapping!$D$5:$D$41,MATCH($D44,Mapping!$A$5:$A$41,0)),"UNMAPPED") -> Current assets | G44: =IFERROR(INDEX(Mapping!$E$5:$E$41,MATCH($D44,Mapping!$A$5:$A$41,0)),"UNMAPPED") -> Inventories | H44: =IFERROR(INDEX(Mapping!$F$5:$F$41,MATCH($D44,Mapping!$A$5:$A$41,0)),"UNMAPPED") -> 20 | I44: Work-in-progress | J44: 210 | L44: 180 | N44: =J44-K44 -> 210 | O44: =L44-M44 -> 180
A45: 3113 | B45: Finished Goods | C45: Asset | D45: BS-A-10 | E45: =IFERROR(INDEX(Mapping!$B$5:$B$41,MATCH($D45,Mapping!$A$5:$A$41,0)),"UNMAPPED") -> Balance Sheet | F45: =IFERROR(INDEX(Mapping!$D$5:$D$41,MATCH($D45,Mapping!$A$5:$A$41,0)),"UNMAPPED") -> Current assets | G45: =IFERROR(INDEX(Mapping!$E$5:$E$41,MATCH($D45,Mapping!$A$5:$A$41,0)),"UNMAPPED") -> Inventories | H45: =IFERROR(INDEX(Mapping!$F$5:$F$41,MATCH($D45,Mapping!$A$5:$A$41,0)),"UNMAPPED") -> 20 | I45: Finished goods | J45: 360 | L45: 320 | N45: =J45-K45 -> 360 | O45: =L45-M45 -> 320
A46: 3114 | B46: Stores, Spares & Packing Materials | C46: Asset | D46: BS-A-10 | E46: =IFERROR(INDEX(Mapping!$B$5:$B$41,MATCH($D46,Mapping!$A$5:$A$41,0)),"UNMAPPED") -> Balance Sheet | F46: =IFERROR(INDEX(Mapping!$D$5:$D$41,MATCH($D46,Mapping!$A$5:$A$41,0)),"UNMAPPED") -> Current assets | G46: =IFERROR(INDEX(Mapping!$E$5:$E$41,MATCH($D46,Mapping!$A$5:$A$41,0)),"UNMAPPED") -> Inventories | H46: =IFERROR(INDEX(Mapping!$F$5:$F$41,MATCH($D46,Mapping!$A$5:$A$41,0)),"UNMAPPED") -> 20 | I46: Stores and spares | J46: 65 | L46: 60 | N46: =J46-K46 -> 65 | O46: =L46-M46 -> 60
A47: 3121 | B47: Trade Receivables - Domestic & Export (Gross) | C47: Asset | D47: BS-A-11 | E47: =IFERROR(INDEX(Mapping!$B$5:$B$41,MATCH($D47,Mapping!$A$5:$A$41,0)),"UNMAPPED") -> Balance Sheet | F47: =IFERROR(INDEX(Mapping!$D$5:$D$41,MATCH($D47,Mapping!$A$5:$A$41,0)),"UNMAPPED") -> Current assets | G47: =IFERROR(INDEX(Mapping!$E$5:$E$41,MATCH($D47,Mapping!$A$5:$A$41,0)),"UNMAPPED") -> Trade receivables | H47: =IFERROR(INDEX(Mapping!$F$5:$F$41,MATCH($D47,Mapping!$A$5:$A$41,0)),"UNMAPPED") -> 21 | I47: Trade receivables - considered good, unsecured | J47: 1480 | L47: 1300 | N47: =J47-K47 -> 1480 | O47: =L47-M47 -> 1300
...

Sheet Mapping
A1: Schedule III Line Item Master (Division I)
A2: Each Mapping Code ties a GL account to one Schedule III line item. Note numbers are illustrative.
A4: Mapping Code | B4: Statement | C4: Section | D4: Sub-section | E4: Schedule III Line Item | F4: Note No. | G4: Normal Balance | H4: Schedule III Reference
A5: BS-EL-01 | B5: Balance Sheet | C5: Equity and Liabilities | D5: Shareholders' funds | E5: Share capital | F5: 1 | G5: Cr | H5: Sch III Part I, I.1(a)
A6: BS-EL-02 | B6: Balance Sheet | C6: Equity and Liabilities | D6: Shareholders' funds | E6: Reserves and surplus | F6: 2 | G6: Cr | H6: Sch III Part I, I.1(b)
A7: BS-EL-03 | B7: Balance Sheet | C7: Equity and Liabilities | D7: Non-current liabilities | E7: Long-term borrowings | F7: 3 | G7: Cr | H7: Sch III Part I, I.3(a)
A8: BS-EL-04 | B8: Balance Sheet | C8: Equity and Liabilities | D8: Non-current liabilities | E8: Deferred tax liabilities (net) | F8: 4 | G8: Cr | H8: Sch III Part I, I.3(b)
A9: BS-EL-05 | B9: Balance Sheet | C9: Equity and Liabilities | D9: Non-current liabilities | E9: Other long-term liabilities | F9: 5 | G9: Cr | H9: Sch III Part I, I.3(c)
A10: BS-EL-06 | B10: Balance Sheet | C10: Equity and Liabilities | D10: Non-current liabilities | E10: Long-term provisions | F10: 6 | G10: Cr | H10: Sch III Part I, I.3(d)
A11: BS-EL-07 | B11: Balance Sheet | C11: Equity and Liabilities | D11: Current liabilities | E11: Short-term borrowings | F11: 7 | G11: Cr | H11: Sch III Part I, I.4(a)
A12: BS-EL-08 | B12: Balance Sheet | C12: Equity and Liabilities | D12: Current liabilities | E12: Trade payables | F12: 8 | G12: Cr | H12: Sch III Part I, I.4(b)
A13: BS-EL-09 | B13: Balance Sheet | C13: Equity and Liabilities | D13: Current liabilities | E13: Other current liabilities | F13: 9 | G13: Cr | H13: Sch III Part I, I.4(c)
A14: BS-EL-10 | B14: Balance Sheet | C14: Equity and Liabilities | D14: Current liabilities | E14: Short-term provisions | F14: 10 | G14: Cr | H14: Sch III Part I, I.4(d)
A15: BS-A-01 | B15: Balance Sheet | C15: Assets | D15: Non-current assets | E15: Fixed assets - Tangible assets | F15: 11 | G15: Dr | H15: Sch III Part I, II.1(a)(i)
A16: BS-A-02 | B16: Balance Sheet | C16: Assets | D16: Non-current assets | E16: Fixed assets - Intangible assets | F16: 12 | G16: Dr | H16: Sch III Part I, II.1(a)(ii)
... A41: PL-12 | B41: Statement of P&L | C41: Expenses | D41: Tax expense | E41: Tax expense - Deferred tax | F41: 37 | G41: Dr | H41: Sch III Part II, VIII(2)

Sheet Balance Sheet
A1: XYZ Manufacturing Private Limited
A2: Balance Sheet (Schedule III, Division I, Part I) as at 31 March - INR in Lakhs
A4: Map Code | B4: Particulars | C4: Note No. | D4: CY 31-Mar-2026 | E4: PY 31-Mar-2025
B5: I. EQUITY AND LIABILITIES
B6: 1. Shareholders' funds
A7: BS-EL-01 | B7: (a) Share capital | C7: =IFERROR(INDEX(Mapping!$F$5:$F$41,MATCH("BS-EL-01",Mapping!$A$5:$A$41,0)),"") -> 1 | D7: =-SUMIFS('Trial Balance'!$N$5:$N$94,'Trial Balance'!$D$5:$D$94,$A7) -> 1000 | E7: =-SUMIFS('Trial Balance'!$O$5:$O$94,'Trial Balance'!$D$5:$D$94,$A7) -> 1000
A8: BS-EL-02 | B8: (b) Reserves and surplus | C8: =IFERROR(INDEX(Mapping!$F$5:$F$41,MATCH("BS-EL-02",Mapping!$A$5:$A$41,0)),"") -> 2 | D8: =-SUMIFS('Trial Balance'!$N$5:$N$94,'Trial Balance'!$D$5:$D$94,$A8)+'Statement of P&L'!D23 -> 2617 | E8: =-SUMIFS('Trial Balance'!$O$5:$O$94,'Trial Balance'!$D$5:$D$94,$A8)+'Statement of P&L'!E23 -> 1871
B9: Total shareholders' funds | D9: =SUM(D7:D8) -> 3617 | E9: =SUM(E7:E8) -> 2871
B10: 2. Non-current liabilities
A11: BS-EL-03 | B11: (a) Long-term borrowings | C11: =IFERROR(INDEX(Mapping!$F$5:$F$41,MATCH("BS-EL-03",Mapping!$A$5:$A$41,0)),"") -> 3 | D11: =-SUMIFS('Trial Balance'!$N$5:$N$94,'Trial Balance'!$D$5:$D$94,$A11) -> 1200 | E11: =-SUMIFS('Trial Balance'!$O$5:$O$94,'Trial Balance'!$D$5:$D$94,$A11) -> 1500
A12: BS-EL-04 | B12: (b) Deferred tax liabilities (net) | C12: =IFERROR(INDEX(Mapping!$F$5:$F$41,MATCH("BS-EL-04",Mapping!$A$5:$A$41,0)),"") -> 4 | D12: =-SUMIFS('Trial Balance'!$N$5:$N$94,'Trial Balance'!$D$5:$D$94,$A12) -> 95 | E12: =-SUMIFS('Trial Balance'!$O$5:$O$94,'Trial Balance'!$D$5:$D$94,$A12) -> 80
A13: BS-EL-05 | B13: (c) Other long-term liabilities | C13: =IFERROR(INDEX(Mapping!$F$5:$F$41,MATCH("BS-EL-05",Mapping!$A$5:$A$41,0)),"") -> 5 | D13: =-SUMIFS('Trial Balance'!$N$5:$N$94,'Trial Balance'!$D$5:$D$94,$A13) -> 0 | E13: =-SUMIFS('Trial Balance'!$O$5:$O$94,'Trial Balance'!$D$5:$D$94,$A13) -> 0
A14: BS-EL-06 | B14: (d) Long-term provisions | C14: =IFERROR(INDEX(Mapping!$F$5:$F$41,MATCH("BS-EL-06",Mapping!$A$5:$A$41,0)),"") -> 6 | D14: =-SUMIFS('Trial Balance'!$N$5:$N$94,'Trial Balance'!$D$5:$D$94,$A14) -> 150 | E14: =-SUMIFS('Trial Balance'!$O$5:$O$94,'Trial Balance'!$D$5:$D$94,$A14) -> 120
B15: Total non-current liabilities | D15: =SUM(D11:D14) -> 1445 | E15: =SUM(E11:E14) -> 1700
B16: 3. Current liabilities
A17: BS-EL-07 | B17: (a) Short-term borrowings | C17: =IFERROR(INDEX(Mapping!$F$5:$F$41,MATCH("BS-EL-07",Mapping!$A$5:$A$41,0)),"") -> 7 | D17: =-SUMIFS('Trial Balance'!$N$5:$N$94,'Trial Balance'!$D$5:$D$94,$A17) -> 500 | E17: =-SUMIFS('Trial Balance'!$O$5:$O$94,'Trial Balance'!$D$5:$D$94,$A17) -> 600
A18: BS-EL-08 | B18: (b) Trade payables | C18: =IFERROR(INDEX(Mapping!$F$5:$F$41,MATCH("BS-EL-08",Mapping!$A$5:$A$41,0)),"") -> 8 | D18: =-SUMIFS('Trial Balance'!$N$5:$N$94,'Trial Balance'!$D$5:$D$94,$A18) -> 1100 | E18: =-SUMIFS('Trial Balance'!$O$5:$O$94,'Trial Balance'!$D$5:$D$94,$A18) -> 1000
A19: BS-EL-09 | B19: (c) Other current liabilities | C19: =IFERROR(INDEX(Mapping!$F$5:$F$41,MATCH("BS-EL-09",Mapping!$A$5:$A$41,0)),"") -> 9 | D19: =-SUMIFS('Trial Balance'!$N$5:$N$94,'Trial Balance'!$D$5:$D$94,$A19) -> 580 | E19: =-SUMIFS('Trial Balance'!$O$5:$O$94,'Trial Balance'!$D$5:$D$94,$A19) -> 532
A20: BS-EL-10 | B20: (d) Short-term provisions | C20: =IFERROR(INDEX(Mapping!$F$5:$F$41,MATCH("BS-EL-10",Mapping!$A$5:$A$41,0)),"") -> 10 | D20: =-SUMIFS('Trial Balance'!$N$5:$N$94,'Trial Balance'!$D$5:$D$94,$A20) -> 245 | E20: =-SUMIFS('Trial Balance'!$O$5:$O$94,'Trial Balance'!$D$5:$D$94,$A20) -> 205
B21: Total current liabilities | D21: =SUM(D17:D20) -> 2425 | E21: =SUM(E17:E20) -> 2337
B22: TOTAL EQUITY AND LIABILITIES | D22: =D9+D15+D21 -> 7487 | E22: =E9+E15+E21 -> 6908
B24: II. ASSETS
B25: 1. Non-current assets
A26: BS-A-01 | B26: (a) Fixed assets - (i) Tangible assets | C26: =IFERROR(INDEX(Mapping!$F$5:$F$41,MATCH("BS-A-01",Mapping!$A$5:$A$41,0)),"") -> 11 | D26: =SUMIFS('Trial Balance'!$N$5:$N$94,'Trial Balance'!$D$5:$D$94,$A26) -> 3225 | E26: =SUMIFS('Trial Balance'!$O$5:$O$94,'Trial Balance'!$D$5:$D$94,$A26) -> 3240
A27: BS-A-02 | B27: (ii) Intangible assets | C27: =IFERROR(INDEX(Mapping!$F$5:$F$41,MATCH("BS-A-02",Mapping!$A$5:$A$41,0)),"") -> 12 | D27: =SUMIFS('Trial Balance'!$N$5:$N$94,'Trial Balance'!$D$5:$D$94,$A27) -> 55 | E27: =SUMIFS('Trial Balance'!$O$5:$O$94,'Trial Balance'!$D$5:$D$94,$A27) -> 50
A28: BS-A-03 | B28: (iii) Capital work-in-progress | C28: =IFERROR(INDEX(Mapping!$F$5:$F$41,MATCH("BS-A-03",Mapping!$A$5:$A$41,0)),"") -> 13 | D28: =SUMIFS('Trial Balance'!$N$5:$N$94,'Trial Balance'!$D$5:$D$94,$A28) -> 200 | E28: =SUMIFS('Trial Balance'!$O$5:$O$94,'Trial Balance'!$D$5:$D$94,$A28) -> 150
A29: BS-A-04 | B29: (iv) Intangible assets under development | C29: =IFERROR(INDEX(Mapping!$F$5:$F$41,MATCH("BS-A-04",Mapping!$A$5:$A$41,0)),"") -> 14 | D29: =SUMIFS('Trial Balance'!$N$5:$N$94,'Trial Balance'!$D$5:$D$94,$A29) -> 0 | E29: =SUMIFS('Trial Balance'!$O$5:$O$94,'Trial Balance'!$D$5:$D$94,$A29) -> 0
A30: BS-A-05 | B30: (b) Non-current investments | C30: =IFERROR(INDEX(Mapping!$F$5:$F$41,MATCH("BS-A-05",Mapping!$A$5:$A$41,0)),"") -> 15 | D30: =SUMIFS('Trial Balance'!$N$5:$N$94,'Trial Balance'!$D$5:$D$94,$A30) -> 250 | E30: =SUMIFS('Trial Balance'!$O$5:$O$94,'Trial Balance'!$D$5:$D$94,$A30) -> 250
A31: BS-A-06 | B31: (c) Deferred tax assets (net) | C31: =IFERROR(INDEX(Mapping!$F$5:$F$41,MATCH("BS-A-06",Mapping!$A$5:$A$41,0)),"") -> 16 | D31: =SUMIFS('Trial Balance'!$N$5:$N$94,'Trial Balance'!$D$5:$D$94,$A31) -> 0 | E31: =SUMIFS('Trial Balance'!$O$5:$O$94,'Trial Balance'!$D$5:$D$94,$A31) -> 0
A32: BS-A-07 | B32: (d) Long-term loans and advances | C32: =IFERROR(INDEX(Mapping!$F$5:$F$41,MATCH("BS-A-07",Mapping!$A$5:$A$41,0)),"") -> 17 | D32: =SUMIFS('Trial Balance'!$N$5:$N$94,'Trial Balance'!$D$5:$D$94,$A32) -> 95 | E32: =SUMIFS('Trial Balance'!$O$5:$O$94,'Trial Balance'!$D$5:$D$94,$A32) -> 100
A33: BS-A-08 | B33: (e) Other non-current assets | C33: =IFERROR(INDEX(Mapping!$F$5:$F$41,MATCH("BS-A-08",Mapping!$A$5:$A$41,0)),"") -> 18 | D33: =SUMIFS('Trial Balance'!$N$5:$N$94,'Trial Balance'!$D$5:$D$94,$A33) -> 50 | E33: =SUMIFS('Trial Balance'!$O$5:$O$94,'Trial Balance'!$D$5:$D$94,$A33) -> 50
B34: Total non-current assets | D34: =SUM(D26:D33) -> 3875 | E34: =SUM(E26:E33) -> 3840
B35: 2. Current assets
A36: BS-A-09 | B36: (a) Current investments | C36: =IFERROR(INDEX(Mapping!$F$5:$F$41,MATCH("BS-A-09",Mapping!$A$5:$A$41,0)),"") -> 19 | D36: =SUMIFS('Trial Balance'!$N$5:$N$94,'Trial Balance'!$D$5:$D$94,$A36) -> 150 | E36: =SUMIFS('Trial Balance'!$O$5:$O$94,'Trial Balance'!$D$5:$D$94,$A36) -> 100
A37: BS-A-10 | B37: (b) Inventories | C37: =IFERROR(INDEX(Mapping!$F$5:$F$41,MATCH("BS-A-10",Mapping!$A$5:$A$41,0)),"") -> 20 | D37: =SUMIFS('Trial Balance'!$N$5:$N$94,'Trial Balance'!$D$5:$D$94,$A37) -> 1155 | E37: =SUMIFS('Trial Balance'!$O$5:$O$94,'Trial Balance'!$D$5:$D$94,$A37) -> 1010
A38: BS-A-11 | B38: (c) Trade receivables | C38: =IFERROR(INDEX(Mapping!$F$5:$F$41,MATCH("BS-A-11",Mapping!$A$5:$A$41,0)),"") -> 21 | D38: =SUMIFS('Trial Balance'!$N$5:$N$94,'Trial Balance'!$D$5:$D$94,$A38) -> 1425 | E38: =SUMIFS('Trial Balance'!$O$5:$O$94,'Trial Balance'!$D$5:$D$94,$A38) -> 1260
A39: BS-A-12 | B39: (d) Cash and cash equivalents | C39: =IFERROR(INDEX(Mapping!$F$5:$F$41,MATCH("BS-A-12",Mapping!$A$5:$A$41,0)),"") -> 22 | D39: =SUMIFS('Trial Balance'!$N$5:$N$94,'Trial Balance'!$D$5:$D$94,$A39) -> 294 | E39: =SUMIFS('Trial Balance'!$O$5:$O$94,'Trial Balance'!$D$5:$D$94,$A39) -> 215
A40: BS-A-13 | B40: (e) Other bank balances | C40: =IFERROR(INDEX(Mapping!$F$5:$F$41,MATCH("BS-A-13",Mapping!$A$5:$A$41,0)),"") -> 23 | D40: =SUMIFS('Trial Balance'!$N$5:$N$94,'Trial Balance'!$D$5:$D$94,$A40) -> 100 | E40: =SUMIFS('Trial Balance'!$O$5:$O$94,'Trial Balance'!$D$5:$D$94,$A40) -> 80
A41: BS-A-14 | B41: (f) Short-term loans and advances | C41: =IFERROR(INDEX(Mapping!$F$5:$F$41,MATCH("BS-A-14",Mapping!$A$5:$A$41,0)),"") -> 24 | D41: =SUMIFS('Trial Balance'!$N$5:$N$94,'Trial Balance'!$D$5:$D$94,$A41) -> 448 | E41: =SUMIFS('Trial Balance'!$O$5:$O$94,'Trial Balance'!$D$5:$D$94,$A41) -> 370
A42: BS-A-15 | B42: (g) Other current assets | C42: =IFERROR(INDEX(Mapping!$F$5:$F$41,MATCH("BS-A-15",Mapping!$A$5:$A$41,0)),"") -> 25 | D42: =SUMIFS('Trial Balance'!$N$5:$N$94,'Trial Balance'!$D$5:$D$94,$A42) -> 40 | E42: =SUMIFS('Trial Balance'!$O$5:$O$94,'Trial Balance'!$D$5:$D$94,$A42) -> 33
...

Sheet Statement of P&L
A1: XYZ Manufacturing Private Limited
A2: Statement of Profit and Loss (Schedule III, Division I, Part II) - INR in Lakhs
A4: Map Code | B4: Particulars | C4: Note No. | D4: CY FY 2025-26 | E4: PY FY 2024-25
A5: PL-01 | B5: I. Revenue from operations | C5: =IFERROR(INDEX(Mapping!$F$5:$F$41,MATCH("PL-01",Mapping!$A$5:$A$41,0)),"") -> 26 | D5: =-SUMIFS('Trial Balance'!$N$5:$N$94,'Trial Balance'!$D$5:$D$94,$A5) -> 9375 | E5: =-SUMIFS('Trial Balance'!$O$5:$O$94,'Trial Balance'!$D$5:$D$94,$A5) -> 8360
A6: PL-02 | B6: II. Other income | C6: =IFERROR(INDEX(Mapping!$F$5:$F$41,MATCH("PL-02",Mapping!$A$5:$A$41,0)),"") -> 27 | D6: =-SUMIFS('Trial Balance'!$N$5:$N$94,'Trial Balance'!$D$5:$D$94,$A6) -> 34 | E6: =-SUMIFS('Trial Balance'!$O$5:$O$94,'Trial Balance'!$D$5:$D$94,$A6) -> 27
B7: III. Total revenue (I + II) | D7: =D5+D6 -> 9409 | E7: =E5+E6 -> 8387
B8: IV. Expenses:
A9: PL-03 | B9: Cost of materials consumed | C9: =IFERROR(INDEX(Mapping!$F$5:$F$41,MATCH("PL-03",Mapping!$A$5:$A$41,0)),"") -> 28 | D9: =SUMIFS('Trial Balance'!$N$5:$N$94,'Trial Balance'!$D$5:$D$94,$A9) -> 5500 | E9: =SUMIFS('Trial Balance'!$O$5:$O$94,'Trial Balance'!$D$5:$D$94,$A9) -> 5000
A10: PL-04 | B10: Purchases of stock-in-trade | C10: =IFERROR(INDEX(Mapping!$F$5:$F$41,MATCH("PL-04",Mapping!$A$5:$A$41,0)),"") -> 29 | D10: =SUMIFS('Trial Balance'!$N$5:$N$94,'Trial Balance'!$D$5:$D$94,$A10) -> 0 | E10: =SUMIFS('Trial Balance'!$O$5:$O$94,'Trial Balance'!$D$5:$D$94,$A10) -> 0
A11: PL-05 | B11: Changes in inventories of finished goods, work-in-progress and stock-in-trade | C11: =IFERROR(INDEX(Mapping!$F$5:$F$41,MATCH("PL-05",Mapping!$A$5:$A$41,0)),"") -> 30 | D11: =SUMIFS('Trial Balance'!$N$5:$N$94,'Trial Balance'!$D$5:$D$94,$A11) -> -70 | E11: =SUMIFS('Trial Balance'!$O$5:$O$94,'Trial Balance'!$D$5:$D$94,$A11) -> -40
A12: PL-06 | B12: Employee benefits expense | C12: =IFERROR(INDEX(Mapping!$F$5:$F$41,MATCH("PL-06",Mapping!$A$5:$A$41,0)),"") -> 31 | D12: =SUMIFS('Trial Balance'!$N$5:$N$94,'Trial Balance'!$D$5:$D$94,$A12) -> 1169 | E12: =SUMIFS('Trial Balance'!$O$5:$O$94,'Trial Balance'!$D$5:$D$94,$A12) -> 1050
A13: PL-07 | B13: Finance costs | C13: =IFERROR(INDEX(Mapping!$F$5:$F$41,MATCH("PL-07",Mapping!$A$5:$A$41,0)),"") -> 32 | D13: =SUMIFS('Trial Balance'!$N$5:$N$94,'Trial Balance'!$D$5:$D$94,$A13) -> 194 | E13: =SUMIFS('Trial Balance'!$O$5:$O$94,'Trial Balance'!$D$5:$D$94,$A13) -> 218
A14: PL-08 | B14: Depreciation and amortisation expense | C14: =IFERROR(INDEX(Mapping!$F$5:$F$41,MATCH("PL-08",Mapping!$A$5:$A$41,0)),"") -> 33 | D14: =SUMIFS('Trial Balance'!$N$5:$N$94,'Trial Balance'!$D$5:$D$94,$A14) -> 370 | E14: =SUMIFS('Trial Balance'!$O$5:$O$94,'Trial Balance'!$D$5:$D$94,$A14) -> 314
A15: PL-09 | B15: Other expenses | C15: =IFERROR(INDEX(Mapping!$F$5:$F$41,MATCH("PL-09",Mapping!$A$5:$A$41,0)),"") -> 34 | D15: =SUMIFS('Trial Balance'!$N$5:$N$94,'Trial Balance'!$D$5:$D$94,$A15) -> 1229 | E15: =SUMIFS('Trial Balance'!$O$5:$O$94,'Trial Balance'!$D$5:$D$94,$A15) -> 1082
B16: Total expenses | D16: =SUM(D9:D15) -> 8392 | E16: =SUM(E9:E15) -> 7624
B17: V. Profit before exceptional items and tax (III - IV) | D17: =D7-D16 -> 1017 | E17: =E7-E16 -> 763
A18: PL-10 | B18: VI. Exceptional items | C18: =IFERROR(INDEX(Mapping!$F$5:$F$41,MATCH("PL-10",Mapping!$A$5:$A$41,0)),"") -> 35 | D18: =SUMIFS('Trial Balance'!$N$5:$N$94,'Trial Balance'!$D$5:$D$94,$A18) -> 0 | E18: =SUMIFS('Trial Balance'!$O$5:$O$94,'Trial Balance'!$D$5:$D$94,$A18) -> 0
B19: VII. Profit before tax (V - VI) | D19: =D17-D18 -> 1017 | E19: =E17-E18 -> 763
B20: VIII. Tax expense:
A21: PL-11 | B21: (1) Current tax | C21: =IFERROR(INDEX(Mapping!$F$5:$F$41,MATCH("PL-11",Mapping!$A$5:$A$41,0)),"") -> 36 | D21: =SUMIFS('Trial Balance'!$N$5:$N$94,'Trial Balance'!$D$5:$D$94,$A21) -> 256 | E21: =SUMIFS('Trial Balance'!$O$5:$O$94,'Trial Balance'!$D$5:$D$94,$A21) -> 195
A22: PL-12 | B22: (2) Deferred tax | C22: =IFERROR(INDEX(Mapping!$F$5:$F$41,MATCH("PL-12",Mapping!$A$5:$A$41,0)),"") -> 37 | D22: =SUMIFS('Trial Balance'!$N$5:$N$94,'Trial Balance'!$D$5:$D$94,$A22) -> 15 | E22: =SUMIFS('Trial Balance'!$O$5:$O$94,'Trial Balance'!$D$5:$D$94,$A22) -> 10
B23: IX. Profit for the year (VII - VIII) | D23: =D19-D21-D22 -> 746 | E23: =E19-E21-E22 -> 558
B25: Profit for the year ties to Reserves and surplus on the Balance Sheet (opening surplus + profit for the year).

Sheet Checks
A1: Integrity Checks
A3: # | B3: Check | C3: CY | D3: PY | E3: Status
A4: 1 | B4: Trial balance: Total Debit = Total Credit (difference) | C4: ='Trial Balance'!J95-'Trial Balance'!K95 -> 0 | D4: ='Trial Balance'!L95-'Trial Balance'!M95 -> 0 | E4: =IF(AND(ABS(C4)<0.5,ABS(D4)<0.5),"PASS","FAIL") -> PASS
A5: 2 | B5: GL accounts not mapped to a valid Schedule III line (count) | C5: =COUNTIF('Trial Balance'!$E$5:$E$94,"UNMAPPED") -> 0 | D5: =COUNTIF('Trial Balance'!$E$5:$E$94,"UNMAPPED") -> 0 | E5: =IF(AND(ABS(C5)<0.5,ABS(D5)<0.5),"PASS","FAIL") -> PASS
A6: 3 | B6: Balance Sheet: Total assets - Total equity & liabilities | C6: ='Balance Sheet'!D46 -> 0 | D6: ='Balance Sheet'!E46 -> 0 | E6: =IF(AND(ABS(C6)<0.5,ABS(D6)<0.5),"PASS","FAIL") -> PASS
A7: 4 | B7: Opening surplus (CY) = PY opening surplus + PY profit for the year | C7: =-'Trial Balance'!N8-(-'Trial Balance'!O8+'Statement of P&L'!E23) -> 0 | D7: =0 -> 0 | E7: =IF(AND(ABS(C7)<0.5,ABS(D7)<0.5),"PASS","FAIL") -> PASS
A8: 5 | B8: Depreciation & amortisation (P&L) = movement in accumulated depreciation/amortisation (CY) | C8: ='Statement of P&L'!D14-(SUMIFS('Trial Balance'!$K$5:$K$94,'Trial Balance'!$A$5:$A$94,">=3011",'Trial Balance'!$A$5:$A$94,"<=3022")-SUMIFS('Trial Balance'!$M$5:$M$94,'Trial Balance'!$A$5:$A$94,">=3011",'Trial Balance'!$A$5:$A$94,"<=3022")) -> 0 | D8: =0 -> 0 | E8: =IF(AND(ABS(C8)<0.5,ABS(D8)<0.5),"PASS","FAIL") -> PASS
A9: 6 | B9: Provision for doubtful debts: P&L charge = movement in provision (CY) | C9: ='Trial Balance'!J90-('Trial Balance'!K48-'Trial Balance'!M48) -> 0 | D9: =0 -> 0 | E9: =IF(AND(ABS(C9)<0.5,ABS(D9)<0.5),"PASS","FAIL") -> PASS
A10: 7 | B10: Deferred tax: P&L charge = movement in DTL (CY) | C10: ='Statement of P&L'!D22-('Balance Sheet'!D12-'Balance Sheet'!E12) -> 0 | D10: =0 -> 0 | E10: =IF(AND(ABS(C10)<0.5,ABS(D10)<0.5),"PASS","FAIL") -> PASS
B12: OVERALL | E12: =IF(COUNTIF(E4:E10,"PASS")=7,"ALL PASS","REVIEW") -> ALL PASS
